
2022-05-11 03:29:04,329 INFO: errors [in /home/mubrik/Documents/python/projects/fyyur_01/app.py:507]
2022-05-11 03:29:23,987 ERROR: Exception on /shows [GET] [in /home/mubrik/Documents/python/projects/fyyur_01/fyyur/lib/python3.10/site-packages/flask/app.py:1455]
Traceback (most recent call last):
  File "/home/mubrik/Documents/python/projects/fyyur_01/fyyur/lib/python3.10/site-packages/flask/app.py", line 2077, in wsgi_app
    response = self.full_dispatch_request()
  File "/home/mubrik/Documents/python/projects/fyyur_01/fyyur/lib/python3.10/site-packages/flask/app.py", line 1525, in full_dispatch_request
    rv = self.handle_user_exception(e)
  File "/home/mubrik/Documents/python/projects/fyyur_01/fyyur/lib/python3.10/site-packages/flask/app.py", line 1523, in full_dispatch_request
    rv = self.dispatch_request()
  File "/home/mubrik/Documents/python/projects/fyyur_01/fyyur/lib/python3.10/site-packages/flask/app.py", line 1509, in dispatch_request
    return self.ensure_sync(self.view_functions[rule.endpoint])(**req.view_args)
  File "/home/mubrik/Documents/python/projects/fyyur_01/app.py", line 470, in shows
    return render_template('pages/shows.html', shows=data)
  File "/home/mubrik/Documents/python/projects/fyyur_01/fyyur/lib/python3.10/site-packages/flask/templating.py", line 148, in render_template
    return _render(
  File "/home/mubrik/Documents/python/projects/fyyur_01/fyyur/lib/python3.10/site-packages/flask/templating.py", line 128, in _render
    rv = template.render(context)
  File "/home/mubrik/Documents/python/projects/fyyur_01/fyyur/lib/python3.10/site-packages/jinja2/environment.py", line 1301, in render
    self.environment.handle_exception()
  File "/home/mubrik/Documents/python/projects/fyyur_01/fyyur/lib/python3.10/site-packages/jinja2/environment.py", line 936, in handle_exception
    raise rewrite_traceback_stack(source=source)
  File "/home/mubrik/Documents/python/projects/fyyur_01/templates/pages/shows.html", line 1, in top-level template code
    {% extends 'layouts/main.html' %}
  File "/home/mubrik/Documents/python/projects/fyyur_01/templates/layouts/main.html", line 103, in top-level template code
    {% block content %}{% endblock %}
  File "/home/mubrik/Documents/python/projects/fyyur_01/templates/pages/shows.html", line 9, in block 'content'
    <h4>{{ show.start_time|datetime('full') }}</h4>
  File "/home/mubrik/Documents/python/projects/fyyur_01/app.py", line 66, in format_datetime
    date = dateutil.parser.parse(value)
  File "/home/mubrik/Documents/python/projects/fyyur_01/fyyur/lib/python3.10/site-packages/dateutil/parser.py", line 1168, in parse
    return DEFAULTPARSER.parse(timestr, **kwargs)
  File "/home/mubrik/Documents/python/projects/fyyur_01/fyyur/lib/python3.10/site-packages/dateutil/parser.py", line 587, in parse
    if (isinstance(tzinfos, collections.Callable) or
AttributeError: module 'collections' has no attribute 'Callable'
2022-05-11 03:29:27,286 ERROR: Exception on /shows [GET] [in /home/mubrik/Documents/python/projects/fyyur_01/fyyur/lib/python3.10/site-packages/flask/app.py:1455]
Traceback (most recent call last):
  File "/home/mubrik/Documents/python/projects/fyyur_01/fyyur/lib/python3.10/site-packages/flask/app.py", line 2077, in wsgi_app
    response = self.full_dispatch_request()
  File "/home/mubrik/Documents/python/projects/fyyur_01/fyyur/lib/python3.10/site-packages/flask/app.py", line 1525, in full_dispatch_request
    rv = self.handle_user_exception(e)
  File "/home/mubrik/Documents/python/projects/fyyur_01/fyyur/lib/python3.10/site-packages/flask/app.py", line 1523, in full_dispatch_request
    rv = self.dispatch_request()
  File "/home/mubrik/Documents/python/projects/fyyur_01/fyyur/lib/python3.10/site-packages/flask/app.py", line 1509, in dispatch_request
    return self.ensure_sync(self.view_functions[rule.endpoint])(**req.view_args)
  File "/home/mubrik/Documents/python/projects/fyyur_01/app.py", line 470, in shows
    return render_template('pages/shows.html', shows=data)
  File "/home/mubrik/Documents/python/projects/fyyur_01/fyyur/lib/python3.10/site-packages/flask/templating.py", line 148, in render_template
    return _render(
  File "/home/mubrik/Documents/python/projects/fyyur_01/fyyur/lib/python3.10/site-packages/flask/templating.py", line 128, in _render
    rv = template.render(context)
  File "/home/mubrik/Documents/python/projects/fyyur_01/fyyur/lib/python3.10/site-packages/jinja2/environment.py", line 1301, in render
    self.environment.handle_exception()
  File "/home/mubrik/Documents/python/projects/fyyur_01/fyyur/lib/python3.10/site-packages/jinja2/environment.py", line 936, in handle_exception
    raise rewrite_traceback_stack(source=source)
  File "/home/mubrik/Documents/python/projects/fyyur_01/templates/pages/shows.html", line 1, in top-level template code
    {% extends 'layouts/main.html' %}
  File "/home/mubrik/Documents/python/projects/fyyur_01/templates/layouts/main.html", line 103, in top-level template code
    {% block content %}{% endblock %}
  File "/home/mubrik/Documents/python/projects/fyyur_01/templates/pages/shows.html", line 9, in block 'content'
    <h4>{{ show.start_time|datetime('full') }}</h4>
  File "/home/mubrik/Documents/python/projects/fyyur_01/app.py", line 66, in format_datetime
    date = dateutil.parser.parse(value)
  File "/home/mubrik/Documents/python/projects/fyyur_01/fyyur/lib/python3.10/site-packages/dateutil/parser.py", line 1168, in parse
    return DEFAULTPARSER.parse(timestr, **kwargs)
  File "/home/mubrik/Documents/python/projects/fyyur_01/fyyur/lib/python3.10/site-packages/dateutil/parser.py", line 587, in parse
    if (isinstance(tzinfos, collections.Callable) or
AttributeError: module 'collections' has no attribute 'Callable'
